2022-10-20:15:37:14	root	INFO	[Classes.py:482]	Init crawl on http://10.99.0.50/testconf/
2022-10-20:15:37:14	root	INFO	[Classes.py:126]	failed to add node [get] http://10.99.0.50/testconf/, already added
2022-10-20:15:37:14	root	WARNING	[Classes.py:148]	Failed to connect edge, get None (True True False)
2022-10-20:15:37:14	root	INFO	[Functions.py:163]	Check edge: [get] ROOTREQ -(get None[False])-> [get] http://10.99.0.50/testconf/
2022-10-20:15:37:14	root	INFO	[Functions.py:207]	Follow edge: [get] ROOTREQ -(get None[False])-> [get] http://10.99.0.50/testconf/
2022-10-20:15:37:14	root	INFO	[Classes.py:1340]	Current url: http://10.99.0.50/testconf/
2022-10-20:15:37:14	root	INFO	[Classes.py:1341]	Crawl (edge): [get] ROOTREQ -(get None[False])-> [get] http://10.99.0.50/testconf/
2022-10-20:15:37:14	root	WARNING	[Classes.py:1409]	Could not execute javascript function in timeout {'function_id': '684b4b1319ce562e4238e4f8c3eadec6', 'function_name': 'reload', 'time': 65000}
2022-10-20:15:37:14	root	INFO	[Functions.py:889]	NEED TO LOGIN FOR FORM: Form(5, http://10.99.0.50/testconf/signin, post)
2022-10-20:15:37:14	root	INFO	[Classes.py:1418]	Found login form
2022-10-20:15:37:14	root	INFO	[Functions.py:833]	set_form_values got 1
2022-10-20:15:37:14	root	INFO	[Functions.py:846]	set_form_values returned 2
2022-10-20:15:37:14	root	DEBUG	[Functions.py:436]	Filling Form(5, http://10.99.0.50/testconf/signin, post)
2022-10-20:15:37:14	root	INFO	[Functions.py:445]	No alert removed (probably due to there not being any)
2022-10-20:15:37:15	root	WARNING	[Functions.py:511]	Default handling for ('hidden', 'post', '.empty') 
2022-10-20:15:37:15	root	INFO	[Functions.py:574]	Filling in input post
2022-10-20:15:37:15	root	WARNING	[Functions.py:511]	Default handling for ('email', 'email', None) 
2022-10-20:15:37:15	root	INFO	[Functions.py:574]	Filling in input email
2022-10-20:15:37:15	root	WARNING	[Functions.py:511]	Default handling for ('password', 'password', None) 
2022-10-20:15:37:15	root	INFO	[Functions.py:574]	Filling in input password
2022-10-20:15:37:15	root	WARNING	[Functions.py:572]	[inputs] could NOT FIND ('submit', None, None, None)
2022-10-20:15:37:15	root	WARNING	[Functions.py:573]	--{('hidden', 'post', '.empty'): ('hidden', 'post', '.empty'), ('email', 'email', None): ('email', 'email', 'vmuser8080@outlook.com'), ('password', 'password', None): ('password', 'password', 'Vmuser8080@utoronto'), ('submit', '', '', None): ('submit', '', '', False), ('submit', 'start', '1', None): ('submit', 'start', '1', True)}
2022-10-20:15:37:15	root	INFO	[Functions.py:574]	Filling in input 
2022-10-20:15:37:15	root	INFO	[Functions.py:574]	Filling in input start
2022-10-20:15:37:15	root	INFO	[Functions.py:651]	form_fill Clicking on submit button
2022-10-20:15:37:15	root	WARNING	[Functions.py:673]	Cannot click on submit button: (<selenium.webdriver.remote.webelement.WebElement (session="8861675bd25ee46431cd824562da8375", element="57d208f2-2594-4cf4-a1a4-48dbe0702f69")>, ('submit', 'start', '1', True))Form(5, http://10.99.0.50/testconf/signin, post)
2022-10-20:15:37:15	root	INFO	[Functions.py:674]	form_fill Javascript submission of form after failed submit button click
2022-10-20:15:37:15	root	INFO	[Functions.py:684]	No alert removed (probably due to there not being any)
2022-10-20:15:37:15	root	INFO	[Functions.py:698]	No alert removed (probably due to there not being any)
2022-10-20:15:37:16	root	DEBUG	[Urls.py:121]	URLs from extract_urls set()
2022-10-20:15:37:16	root	WARNING	[Forms.py:56]	No inputs founds during parse, falling back to JavaScript
2022-10-20:15:37:16	root	INFO	[Forms.py:66]	Found js form: Form(0, http://10.99.0.50/testconf/signout?post=hin6dsu5tavf, post)
2022-10-20:15:37:17	root	ERROR	[Classes.py:564]	HTTPConnectionPool(host='localhost', port=41267): Max retries exceeded with url: /session/8861675bd25ee46431cd824562da8375/element/3b8bdd85-5175-4776-8717-0f3c0121d257/elements (Caused by NewConnectionError('<urllib3.connection.HTTPConnection object at 0x7f81847af070>: Failed to establish a new connection: [Errno 111] Connection refused'))
2022-10-20:15:37:17	root	ERROR	[Classes.py:566]	Top level error while crawling
2022-10-20:15:37:17	root	WARNING	[Classes.py:1293]	Falling back to GET
2022-10-20:15:37:17	root	WARNING	[Classes.py:1293]	Falling back to GET
2022-10-20:15:37:17	root	INFO	[Functions.py:163]	Check edge: [get] ROOTREQ -(get None[False])-> [get] http://10.99.0.50/testconf/
2022-10-20:15:37:17	root	INFO	[Functions.py:207]	Follow edge: [get] ROOTREQ -(get None[False])-> [get] http://10.99.0.50/testconf/
2022-10-20:15:37:17	root	ERROR	[Classes.py:564]	HTTPConnectionPool(host='localhost', port=41267): Max retries exceeded with url: /session/8861675bd25ee46431cd824562da8375/url (Caused by NewConnectionError('<urllib3.connection.HTTPConnection object at 0x7f8184881f70>: Failed to establish a new connection: [Errno 111] Connection refused'))
2022-10-20:15:37:17	root	ERROR	[Classes.py:566]	Top level error while crawling
2022-10-20:15:37:17	root	INFO	[Functions.py:163]	Check edge: [get] ROOTREQ -(get None[False])-> [get] http://10.99.0.50/testconf/
2022-10-20:15:37:17	root	INFO	[Functions.py:207]	Follow edge: [get] ROOTREQ -(get None[False])-> [get] http://10.99.0.50/testconf/
